Workbook

Sheet Instructions
A1: Sleeve seed workbook
A2: Fill the Sleeves sheet (and the Rules sheet for editions), then load the workbook into the sleeve library. Yellow cells are for you; grey sheets are reference.
A4: THE SHEETS
A5: Sleeves - one row per product in an edition: Variant (implementation type), Category, Sleeve (its name), Edition (blank for the fallback), ProductId, Weight. The last three columns are checks, filled in for you.
A6: Rules - which strategic portfolios each labelled edition is for. Only editions with a label have rules; the fallback never does.
A7: Catalogue - every product id you may use, with its name, vehicle, cost and minimum.
A8: Lists - the values the drop-downs offer.
A10: SLEEVES AND EDITIONS
A11: A sleeve is a name in a category under an implementation type. Its fallback edition (Edition left blank) is what every portfolio gets unless a labelled edition claims it.
A12: A labelled edition (e.g. GBP) is a variant of the same sleeve for particular portfolios. Give it its own product rows under the same Variant, Category and Sleeve, with the label in Edition, and at least one row on the Rules sheet.
A13: Every sleeve needs its fallback. Two editions of one sleeve may not claim the same portfolio, and they may not leave the fallback with no portfolio at all.
A15: RULES
... A43: 5. Restart the service so open pages pick the library up.

Sheet Sleeves
A1: Variant | B1: Category | C1: Sleeve | D1: Edition | E1: ProductId | F1: Weight | G1: Product name | H1: Edition total | I1: Check
A2: Irish Onshore | B2: Asset Allocation Strategies | C2: Tactical Tilt Overlay Portfolio | E2: tactical-tilt-fund-ucits | F2: 1 | G2: =IF(E2="","",IFERROR(VLOOKUP(E2,Catalogue!$A:$B,2,FALSE),"Not in the catalogue")) | H2: =IF(A2="","",SUMIFS($F:$F,$A:$A,A2,$B:$B,B2,$C:$C,C2,$D:$D,D2&"")) | I2: =IF(A2="","",IF(COUNTIF(Catalogue!$A:$A,E2)=0,"Unknown product id",IF(ABS(H2-1)>0.000001,"Edition weights must total exactly 100%",IF(COUNTIFS($A:$A,A2,$B:$B,B2,$C:$C,C2,$D:$D,D2&"",$E:$E,E2)>1,"Product listed twice in this edition","OK"))))
A3: Irish Onshore | B3: Hedge Funds | C3: HFM & ART | E3: gs-absolute-return-ucits | F3: 0.6 | G3: =IF(E3="","",IFERROR(VLOOKUP(E3,Catalogue!$A:$B,2,FALSE),"Not in the catalogue")) | H3: =IF(A3="","",SUMIFS($F:$F,$A:$A,A3,$B:$B,B3,$C:$C,C3,$D:$D,D3&"")) | I3: =IF(A3="","",IF(COUNTIF(Catalogue!$A:$A,E3)=0,"Unknown product id",IF(ABS(H3-1)>0.000001,"Edition weights must total exactly 100%",IF(COUNTIFS($A:$A,A3,$B:$B,B3,$C:$C,C3,$D:$D,D3&"",$E:$E,E3)>1,"Product listed twice in this edition","OK"))))
A4: Irish Onshore | B4: Hedge Funds | C4: HFM & ART | E4: calderwood-global-macro-ucits | F4: 0.4 | G4: =IF(E4="","",IFERROR(VLOOKUP(E4,Catalogue!$A:$B,2,FALSE),"Not in the catalogue")) | H4: =IF(A4="","",SUMIFS($F:$F,$A:$A,A4,$B:$B,B4,$C:$C,C4,$D:$D,D4&"")) | I4: =IF(A4="","",IF(COUNTIF(Catalogue!$A:$A,E4)=0,"Unknown product id",IF(ABS(H4-1)>0.000001,"Edition weights must total exactly 100%",IF(COUNTIFS($A:$A,A4,$B:$B,B4,$C:$C,C4,$D:$D,D4&"",$E:$E,E4)>1,"Product listed twice in this edition","OK"))))
A5: Irish Onshore | B5: Hedge Funds | C5: HFO & ART | E5: calderwood-global-macro-ucits | F5: 0.55 | G5: =IF(E5="","",IFERROR(VLOOKUP(E5,Catalogue!$A:$B,2,FALSE),"Not in the catalogue")) | H5: =IF(A5="","",SUMIFS($F:$F,$A:$A,A5,$B:$B,B5,$C:$C,C5,$D:$D,D5&"")) | I5: =IF(A5="","",IF(COUNTIF(Catalogue!$A:$A,E5)=0,"Unknown product id",IF(ABS(H5-1)>0.000001,"Edition weights must total exactly 100%",IF(COUNTIFS($A:$A,A5,$B:$B,B5,$C:$C,C5,$D:$D,D5&"",$E:$E,E5)>1,"Product listed twice in this edition","OK"))))
A6: Irish Onshore | B6: Hedge Funds | C6: HFO & ART | E6: gs-absolute-return-ucits | F6: 0.45 | G6: =IF(E6="","",IFERROR(VLOOKUP(E6,Catalogue!$A:$B,2,FALSE),"Not in the catalogue")) | H6: =IF(A6="","",SUMIFS($F:$F,$A:$A,A6,$B:$B,B6,$C:$C,C6,$D:$D,D6&"")) | I6: =IF(A6="","",IF(COUNTIF(Catalogue!$A:$A,E6)=0,"Unknown product id",IF(ABS(H6-1)>0.000001,"Edition weights must total exactly 100%",IF(COUNTIFS($A:$A,A6,$B:$B,B6,$C:$C,C6,$D:$D,D6&"",$E:$E,E6)>1,"Product listed twice in this edition","OK"))))
A7: Irish Onshore | B7: Hedge Funds | C7: GMMAP & ART | E7: calderwood-global-macro-ucits | F7: 0.6 | G7: =IF(E7="","",IFERROR(VLOOKUP(E7,Catalogue!$A:$B,2,FALSE),"Not in the catalogue")) | H7: =IF(A7="","",SUMIFS($F:$F,$A:$A,A7,$B:$B,B7,$C:$C,C7,$D:$D,D7&"")) | I7: =IF(A7="","",IF(COUNTIF(Catalogue!$A:$A,E7)=0,"Unknown product id",IF(ABS(H7-1)>0.000001,"Edition weights must total exactly 100%",IF(COUNTIFS($A:$A,A7,$B:$B,B7,$C:$C,C7,$D:$D,D7&"",$E:$E,E7)>1,"Product listed twice in this edition","OK"))))
A8: Irish Onshore | B8: Hedge Funds | C8: GMMAP & ART | E8: gs-absolute-return-ucits | F8: 0.4 | G8: =IF(E8="","",IFERROR(VLOOKUP(E8,Catalogue!$A:$B,2,FALSE),"Not in the catalogue")) | H8: =IF(A8="","",SUMIFS($F:$F,$A:$A,A8,$B:$B,B8,$C:$C,C8,$D:$D,D8&"")) | I8: =IF(A8="","",IF(COUNTIF(Catalogue!$A:$A,E8)=0,"Unknown product id",IF(ABS(H8-1)>0.000001,"Edition weights must total exactly 100%",IF(COUNTIFS($A:$A,A8,$B:$B,B8,$C:$C,C8,$D:$D,D8&"",$E:$E,E8)>1,"Product listed twice in this edition","OK"))))
A9: Irish Onshore | B9: Hedge Funds | C9: Aptitude & ART | E9: gs-absolute-return-ucits | F9: 0.55 | G9: =IF(E9="","",IFERROR(VLOOKUP(E9,Catalogue!$A:$B,2,FALSE),"Not in the catalogue")) | H9: =IF(A9="","",SUMIFS($F:$F,$A:$A,A9,$B:$B,B9,$C:$C,C9,$D:$D,D9&"")) | I9: =IF(A9="","",IF(COUNTIF(Catalogue!$A:$A,E9)=0,"Unknown product id",IF(ABS(H9-1)>0.000001,"Edition weights must total exactly 100%",IF(COUNTIFS($A:$A,A9,$B:$B,B9,$C:$C,C9,$D:$D,D9&"",$E:$E,E9)>1,"Product listed twice in this edition","OK"))))
A10: Irish Onshore | B10: Hedge Funds | C10: Aptitude & ART | E10: calderwood-global-macro-ucits | F10: 0.45 | G10: =IF(E10="","",IFERROR(VLOOKUP(E10,Catalogue!$A:$B,2,FALSE),"Not in the catalogue")) | H10: =IF(A10="","",SUMIFS($F:$F,$A:$A,A10,$B:$B,B10,$C:$C,C10,$D:$D,D10&"")) | I10: =IF(A10="","",IF(COUNTIF(Catalogue!$A:$A,E10)=0,"Unknown product id",IF(ABS(H10-1)>0.000001,"Edition weights must total exactly 100%",IF(COUNTIFS($A:$A,A10,$B:$B,B10,$C:$C,C10,$D:$D,D10&"",$E:$E,E10)>1,"Product listed twice in this edition","OK"))))
A11: Irish Onshore | B11: Hedge Funds | C11: HFO Only | E11: gs-absolute-return-ucits | F11: 0.6 | G11: =IF(E11="","",IFERROR(VLOOKUP(E11,Catalogue!$A:$B,2,FALSE),"Not in the catalogue")) | H11: =IF(A11="","",SUMIFS($F:$F,$A:$A,A11,$B:$B,B11,$C:$C,C11,$D:$D,D11&"")) | I11: =IF(A11="","",IF(COUNTIF(Catalogue!$A:$A,E11)=0,"Unknown product id",IF(ABS(H11-1)>0.000001,"Edition weights must total exactly 100%",IF(COUNTIFS($A:$A,A11,$B:$B,B11,$C:$C,C11,$D:$D,D11&"",$E:$E,E11)>1,"Product listed twice in this edition","OK"))))
A12: Irish Onshore | B12: Hedge Funds | C12: HFO Only | E12: calderwood-global-macro-ucits | F12: 0.4 | G12: =IF(E12="","",IFERROR(VLOOKUP(E12,Catalogue!$A:$B,2,FALSE),"Not in the catalogue")) | H12: =IF(A12="","",SUMIFS($F:$F,$A:$A,A12,$B:$B,B12,$C:$C,C12,$D:$D,D12&"")) | I12: =IF(A12="","",IF(COUNTIF(Catalogue!$A:$A,E12)=0,"Unknown product id",IF(ABS(H12-1)>0.000001,"Edition weights must total exactly 100%",IF(COUNTIFS($A:$A,A12,$B:$B,B12,$C:$C,C12,$D:$D,D12&"",$E:$E,E12)>1,"Product listed twice in this edition","OK"))))
A13: Irish Onshore | B13: Hybrid Fixed Income | C13: SVP | E13: strategic-volatility-premium | F13: 1 | G13: =IF(E13="","",IFERROR(VLOOKUP(E13,Catalogue!$A:$B,2,FALSE),"Not in the catalogue")) | H13: =IF(A13="","",SUMIFS($F:$F,$A:$A,A13,$B:$B,B13,$C:$C,C13,$D:$D,D13&"")) | I13: =IF(A13="","",IF(COUNTIF(Catalogue!$A:$A,E13)=0,"Unknown product id",IF(ABS(H13-1)>0.000001,"Edition weights must total exactly 100%",IF(COUNTIFS($A:$A,A13,$B:$B,B13,$C:$C,C13,$D:$D,D13&"",$E:$E,E13)>1,"Product listed twice in this edition","OK"))))
... A260: US Onshore | B260: Public Equity | C260: US Onshore Concentrated Active Passive (Low TE) | E260: gs-us-focused-value-sma | F260: 0.2 | G260: =IF(E260="","",IFERROR(VLOOKUP(E260,Catalogue!$A:$B,2,FALSE),"Not in the catalogue")) | H260: =IF(A260="","",SUMIFS($F:$F,$A:$A,A260,$B:$B,B260,$C:$C,C260,$D:$D,D260&"")) | I260: =IF(A260="","",IF(COUNTIF(Catalogue!$A:$A,E260)=0,"Unknown product id",IF(ABS(H260-1)>0.000001,"Edition weights must total exactly 100%",IF(COUNTIFS($A:$A,A260,$B:$B,B260,$C:$C,C260,$D:$D,D260&"",$E:$E,E260)>1,"Product listed twice in this edition","OK"))))
G261: =IF(E261="","",IFERROR(VLOOKUP(E261,Catalogue!$A:$B,2,FALSE),"Not in the catalogue")) | H261: =IF(A261="","",SUMIFS($F:$F,$A:$A,A261,$B:$B,B261,$C:$C,C261,$D:$D,D261&"")) | I261: =IF(A261="","",IF(COUNTIF(Catalogue!$A:$A,E261)=0,"Unknown product id",IF(ABS(H261-1)>0.000001,"Edition weights must total exactly 100%",IF(COUNTIFS($A:$A,A261,$B:$B,B261,$C:$C,C261,$D:$D,D261&"",$E:$E,E261)>1,"Product listed twice in this edition","OK"))))
G262: =IF(E262="","",IFERROR(VLOOKUP(E262,Catalogue!$A:$B,2,FALSE),"Not in the catalogue")) | H262: =IF(A262="","",SUMIFS($F:$F,$A:$A,A262,$B:$B,B262,$C:$C,C262,$D:$D,D262&"")) | I262: =IF(A262="","",IF(COUNTIF(Catalogue!$A:$A,E262)=0,"Unknown product id",IF(ABS(H262-1)>0.000001,"Edition weights must total exactly 100%",IF(COUNTIFS($A:$A,A262,$B:$B,B262,$C:$C,C262,$D:$D,D262&"",$E:$E,E262)>1,"Product listed twice in this edition","OK"))))
G263: =IF(E263="","",IFERROR(VLOOKUP(E263,Catalogue!$A:$B,2,FALSE),"Not in the catalogue")) | H263: =IF(A263="","",SUMIFS($F:$F,$A:$A,A263,$B:$B,B263,$C:$C,C263,$D:$D,D263&"")) | I263: =IF(A263="","",IF(COUNTIF(Catalogue!$A:$A,E263)=0,"Unknown product id",IF(ABS(H263-1)>0.000001,"Edition weights must total exactly 100%",IF(COUNTIFS($A:$A,A263,$B:$B,B263,$C:$C,C263,$D:$D,D263&"",$E:$E,E263)>1,"Product listed twice in this edition","OK"))))
G264: =IF(E264="","",IFERROR(VLOOKUP(E264,Catalogue!$A:$B,2,FALSE),"Not in the catalogue")) | H264: =IF(A264="","",SUMIFS($F:$F,$A:$A,A264,$B:$B,B264,$C:$C,C264,$D:$D,D264&"")) | I264: =IF(A264="","",IF(COUNTIF(Catalogue!$A:$A,E264)=0,"Unknown product id",IF(ABS(H264-1)>0.000001,"Edition weights must total exactly 100%",IF(COUNTIFS($A:$A,A264,$B:$B,B264,$C:$C,C264,$D:$D,D264&"",$E:$E,E264)>1,"Product listed twice in this edition","OK"))))
G265: =IF(E265="","",IFERROR(VLOOKUP(E265,Catalogue!$A:$B,2,FALSE),"Not in the catalogue")) | H265: =IF(A265="","",SUMIFS($F:$F,$A:$A,A265,$B:$B,B265,$C:$C,C265,$D:$D,D265&"")) | I265: =IF(A265="","",IF(COUNTIF(Catalogue!$A:$A,E265)=0,"Unknown product id",IF(ABS(H265-1)>0.000001,"Edition weights must total exactly 100%",IF(COUNTIFS($A:$A,A265,$B:$B,B265,$C:$C,C265,$D:$D,D265&"",$E:$E,E265)>1,"Product listed twice in this edition","OK"))))
G266: =IF(E266="","",IFERROR(VLOOKUP(E266,Catalogue!$A:$B,2,FALSE),"Not in the catalogue")) | H266: =IF(A266="","",SUMIFS($F:$F,$A:$A,A266,$B:$B,B266,$C:$C,C266,$D:$D,D266&"")) | I266: =IF(A266="","",IF(COUNTIF(Catalogue!$A:$A,E266)=0,"Unknown product id",IF(ABS(H266-1)>0.000001,"Edition weights must total exactly 100%",IF(COUNTIFS($A:$A,A266,$B:$B,B266,$C:$C,C266,$D:$D,D266&"",$E:$E,E266)>1,"Product listed twice in this edition","OK"))))
G267: =IF(E267="","",IFERROR(VLOOKUP(E267,Catalogue!$A:$B,2,FALSE),"Not in the catalogue")) | H267: =IF(A267="","",SUMIFS($F:$F,$A:$A,A267,$B:$B,B267,$C:$C,C267,$D:$D,D267&"")) | I267: =IF(A267="","",IF(COUNTIF(Catalogue!$A:$A,E267)=0,"Unknown product id",IF(ABS(H267-1)>0.000001,"Edition weights must total exactly 100%",IF(COUNTIFS($A:$A,A267,$B:$B,B267,$C:$C,C267,$D:$D,D267&"",$E:$E,E267)>1,"Product listed twice in this edition","OK"))))
G268: =IF(E268="","",IFERROR(VLOOKUP(E268,Catalogue!$A:$B,2,FALSE),"Not in the catalogue")) | H268: =IF(A268="","",SUMIFS($F:$F,$A:$A,A268,$B:$B,B268,$C:$C,C268,$D:$D,D268&"")) | I268: =IF(A268="","",IF(COUNTIF(Catalogue!$A:$A,E268)=0,"Unknown product id",IF(ABS(H268-1)>0.000001,"Edition weights must total exactly 100%",IF(COUNTIFS($A:$A,A268,$B:$B,B268,$C:$C,C268,$D:$D,D268&"",$E:$E,E268)>1,"Product listed twice in this edition","OK"))))
G269: =IF(E269="","",IFERROR(VLOOKUP(E269,Catalogue!$A:$B,2,FALSE),"Not in the catalogue")) | H269: =IF(A269="","",SUMIFS($F:$F,$A:$A,A269,$B:$B,B269,$C:$C,C269,$D:$D,D269&"")) | I269: =IF(A269="","",IF(COUNTIF(Catalogue!$A:$A,E269)=0,"Unknown product id",IF(ABS(H269-1)>0.000001,"Edition weights must total exactly 100%",IF(COUNTIFS($A:$A,A269,$B:$B,B269,$C:$C,C269,$D:$D,D269&"",$E:$E,E269)>1,"Product listed twice in this edition","OK"))))
G270: =IF(E270="","",IFERROR(VLOOKUP(E270,Catalogue!$A:$B,2,FALSE),"Not in the catalogue")) | H270: =IF(A270="","",SUMIFS($F:$F,$A:$A,A270,$B:$B,B270,$C:$C,C270,$D:$D,D270&"")) | I270: =IF(A270="","",IF(COUNTIF(Catalogue!$A:$A,E270)=0,"Unknown product id",IF(ABS(H270-1)>0.000001,"Edition weights must total exactly 100%",IF(COUNTIFS($A:$A,A270,$B:$B,B270,$C:$C,C270,$D:$D,D270&"",$E:$E,E270)>1,"Product listed twice in this edition","OK"))))
G271: =IF(E271="","",IFERROR(VLOOKUP(E271,Catalogue!$A:$B,2,FALSE),"Not in the catalogue")) | H271: =IF(A271="","",SUMIFS($F:$F,$A:$A,A271,$B:$B,B271,$C:$C,C271,$D:$D,D271&"")) | I271: =IF(A271="","",IF(COUNTIF(Catalogue!$A:$A,E271)=0,"Unknown product id",IF(ABS(H271-1)>0.000001,"Edition weights must total exactly 100%",IF(COUNTIFS($A:$A,A271,$B:$B,B271,$C:$C,C271,$D:$D,D271&"",$E:$E,E271)>1,"Product listed twice in this edition","OK"))))
G272: =IF(E272="","",IFERROR(VLOOKUP(E272,Catalogue!$A:$B,2,FALSE),"Not in the catalogue")) | H272: =IF(A272="","",SUMIFS($F:$F,$A:$A,A272,$B:$B,B272,$C:$C,C272,$D:$D,D272&"")) | I272: =IF(A272="","",IF(COUNTIF(Catalogue!$A:$A,E272)=0,"Unknown product id",IF(ABS(H272-1)>0.000001,"Edition weights must total exactly 100%",IF(COUNTIFS($A:$A,A272,$B:$B,B272,$C:$C,C272,$D:$D,D272&"",$E:$E,E272)>1,"Product listed twice in this edition","OK"))))
... G2000: =IF(E2000="","",IFERROR(VLOOKUP(E2000,Catalogue!$A:$B,2,FALSE),"Not in the catalogue")) | H2000: =IF(A2000="","",SUMIFS($F:$F,$A:$A,A2000,$B:$B,B2000,$C:$C,C2000,$D:$D,D2000&"")) | I2000: =IF(A2000="","",IF(COUNTIF(Catalogue!$A:$A,E2000)=0,"Unknown product id",IF(ABS(H2000-1)>0.000001,"Edition weights must total exactly 100%",IF(COUNTIFS($A:$A,A2000,$B:$B,B2000,$C:$C,C2000,$D:$D,D2000&"",$E:$E,E2000)>1,"Product listed twice in this edition","OK"))))

Sheet Rules
A1: Variant | B1: Category | C1: Sleeve | D1: Edition | E1: Currency | F1: RiskLevel | G1: AllocationType | H1: Check
H2: =IF(A2="","",IF(D2="","An edition needs a label; the fallback has no rules",IF(COUNTIFS(Sleeves!$A:$A,A2,Sleeves!$B:$B,B2,Sleeves!$C:$C,C2,Sleeves!$D:$D,D2)=0,"No Sleeves rows for this edition",IF(AND(E2="",F2="",G2=""),"A rule must name at least one value","OK"))))
H3: =IF(A3="","",IF(D3="","An edition needs a label; the fallback has no rules",IF(COUNTIFS(Sleeves!$A:$A,A3,Sleeves!$B:$B,B3,Sleeves!$C:$C,C3,Sleeves!$D:$D,D3)=0,"No Sleeves rows for this edition",IF(AND(E3="",F3="",G3=""),"A rule must name at least one value","OK"))))
H4: =IF(A4="","",IF(D4="","An edition needs a label; the fallback has no rules",IF(COUNTIFS(Sleeves!$A:$A,A4,Sleeves!$B:$B,B4,Sleeves!$C:$C,C4,Sleeves!$D:$D,D4)=0,"No Sleeves rows for this edition",IF(AND(E4="",F4="",G4=""),"A rule must name at least one value","OK"))))
H5: =IF(A5="","",IF(D5="","An edition needs a label; the fallback has no rules",IF(COUNTIFS(Sleeves!$A:$A,A5,Sleeves!$B:$B,B5,Sleeves!$C:$C,C5,Sleeves!$D:$D,D5)=0,"No Sleeves rows for this edition",IF(AND(E5="",F5="",G5=""),"A rule must name at least one value","OK"))))
H6: =IF(A6="","",IF(D6="","An edition needs a label; the fallback has no rules",IF(COUNTIFS(Sleeves!$A:$A,A6,Sleeves!$B:$B,B6,Sleeves!$C:$C,C6,Sleeves!$D:$D,D6)=0,"No Sleeves rows for this edition",IF(AND(E6="",F6="",G6=""),"A rule must name at least one value","OK"))))
H7: =IF(A7="","",IF(D7="","An edition needs a label; the fallback has no rules",IF(COUNTIFS(Sleeves!$A:$A,A7,Sleeves!$B:$B,B7,Sleeves!$C:$C,C7,Sleeves!$D:$D,D7)=0,"No Sleeves rows for this edition",IF(AND(E7="",F7="",G7=""),"A rule must name at least one value","OK"))))
H8: =IF(A8="","",IF(D8="","An edition needs a label; the fallback has no rules",IF(COUNTIFS(Sleeves!$A:$A,A8,Sleeves!$B:$B,B8,Sleeves!$C:$C,C8,Sleeves!$D:$D,D8)=0,"No Sleeves rows for this edition",IF(AND(E8="",F8="",G8=""),"A rule must name at least one value","OK"))))
H9: =IF(A9="","",IF(D9="","An edition needs a label; the fallback has no rules",IF(COUNTIFS(Sleeves!$A:$A,A9,Sleeves!$B:$B,B9,Sleeves!$C:$C,C9,Sleeves!$D:$D,D9)=0,"No Sleeves rows for this edition",IF(AND(E9="",F9="",G9=""),"A rule must name at least one value","OK"))))
H10: =IF(A10="","",IF(D10="","An edition needs a label; the fallback has no rules",IF(COUNTIFS(Sleeves!$A:$A,A10,Sleeves!$B:$B,B10,Sleeves!$C:$C,C10,Sleeves!$D:$D,D10)=0,"No Sleeves rows for this edition",IF(AND(E10="",F10="",G10=""),"A rule must name at least one value","OK"))))
H11: =IF(A11="","",IF(D11="","An edition needs a label; the fallback has no rules",IF(COUNTIFS(Sleeves!$A:$A,A11,Sleeves!$B:$B,B11,Sleeves!$C:$C,C11,Sleeves!$D:$D,D11)=0,"No Sleeves rows for this edition",IF(AND(E11="",F11="",G11=""),"A rule must name at least one value","OK"))))
H12: =IF(A12="","",IF(D12="","An edition needs a label; the fallback has no rules",IF(COUNTIFS(Sleeves!$A:$A,A12,Sleeves!$B:$B,B12,Sleeves!$C:$C,C12,Sleeves!$D:$D,D12)=0,"No Sleeves rows for this edition",IF(AND(E12="",F12="",G12=""),"A rule must name at least one value","OK"))))
H13: =IF(A13="","",IF(D13="","An edition needs a label; the fallback has no rules",IF(COUNTIFS(Sleeves!$A:$A,A13,Sleeves!$B:$B,B13,Sleeves!$C:$C,C13,Sleeves!$D:$D,D13)=0,"No Sleeves rows for this edition",IF(AND(E13="",F13="",G13=""),"A rule must name at least one value","OK"))))
... H2000: =IF(A2000="","",IF(D2000="","An edition needs a label; the fallback has no rules",IF(COUNTIFS(Sleeves!$A:$A,A2000,Sleeves!$B:$B,B2000,Sleeves!$C:$C,C2000,Sleeves!$D:$D,D2000)=0,"No Sleeves rows for this edition",IF(AND(E2000="",F2000="",G2000=""),"A rule must name at least one value","OK"))))

Sheet Lists
A1: Implementation type (Variant) | B1: Category | C1: Currency | D1: RiskLevel (stored form) | E1: Risk level as the desk says it | F1: AllocationType | G1: Fixed categories (one sleeve per type)
A2: PMG Multi-Asset Portfolio | B2: Investment Grade Fixed Income | C2: USD | D2: LowVol | E2: Low Vol | F2: Full | G2: Asset Allocation Strategies
A3: PMG ESG | B3: Hybrid Fixed Income | C3: GBP | D3: Conservative | E3: Conservative | F3: Core | G3: Hybrid Fixed Income
A4: US Onshore | B4: Other Fixed Income | C4: CHF | D4: ConsMod | E4: Conservative-Moderate | F4: ex-Alts
A5: Irish Onshore | B5: Public Equity | C5: EUR | D5: Moderate | E5: Moderate | F5: ex-HFs
B6: Hedge Funds | D6: ModAgg | E6: Moderate-Aggressive | F6: NA
B7: Private Equity & Other Private Assets | D7: Agg | E7: Aggressive
B8: Asset Allocation Strategies | D8: Higher Risk | E8: Higher Risk
D9: All Equity | E9: All Equity

Sheet Catalogue
A1: ProductId | B1: Name | C1: Asset class | D1: Vehicle | E1: Style | F1: Source | G1: Currency | H1: Liquidity | I1: Cost | J1: Minimum
A2: gsam-core-municipal-sma | B2: GSAM Core Municipal SMA | C2: Municipals | D2: SMA | E2: Active | F2: Internal | G2: USD | H2: Daily | I2: 0.25 | J2: 5000000
A3: gsam-intermediate-credit-sma | B3: GSAM Intermediate Credit SMA | C3: IG Corporate | D3: SMA | E3: Active | F3: Internal | G3: USD | H3: Daily | I3: 0.28 | J3: 5000000
A4: gsam-short-duration-sma | B4: GSAM Short Duration SMA | C4: Short Duration | D4: SMA | E4: Active | F4: Internal | G4: USD | H4: Daily | I4: 0.22 | J4: 5000000
A5: gs-us-corporate-bond-fund | B5: GS US Corporate Bond Fund | C5: IG Corporate | D5: Mutual Fund | E5: Active | F5: Internal | G5: USD | H5: Daily | I5: 0.42 | J5: 1000
A6: ashfield-global-credit-fund | B6: Ashfield Global Credit Fund | C6: IG Corporate | D6: Mutual Fund | E6: Active | F6: External | G6: Local | H6: Daily | I6: 0.55 | J6: 1000
A7: gs-short-duration-income | B7: GS Short Duration Income | C7: Short Duration | D7: Mutual Fund | E7: Active | F7: Internal | G7: USD | H7: Daily | I7: 0.38 | J7: 1000
A8: gs-access-ig-corporate-etf | B8: GS Access IG Corporate ETF | C8: IG Corporate | D8: ETF | E8: Passive | F8: Internal | G8: USD | H8: Daily | I8: 0.14
A9: gs-access-treasury-0-1-etf | B9: GS Access Treasury 0-1 ETF | C9: Government | D9: ETF | E9: Passive | F9: Internal | G9: USD | H9: Daily | I9: 0.12
A10: gs-core-fixed-income-fund | B10: GS Core Fixed Income Fund | C10: Aggregate | D10: Mutual Fund | E10: Active | F10: Internal | G10: USD | H10: Daily | I10: 0.46 | J10: 1000
A11: gs-high-yield-fund | B11: GS High Yield Fund | C11: High Yield | D11: Mutual Fund | E11: Active | F11: Internal | G11: USD | H11: Daily | I11: 0.72 | J11: 1000
A12: gs-emerging-markets-debt | B12: GS Emerging Markets Debt | C12: EM Debt | D12: Mutual Fund | E12: Active | F12: Internal | G12: USD | H12: Daily | I12: 0.85 | J12: 1000
A13: gs-strategic-income-fund | B13: GS Strategic Income Fund | C13: Multi-Sector | D13: Mutual Fund | E13: Active | F13: Internal | G13: USD | H13: Daily | I13: 0.79 | J13: 1000
A14: calderwood-local-em-debt | B14: Calderwood Local EM Debt | C14: EM Debt | D14: Mutual Fund | E14: Active | F14: External | G14: Local | H14: Daily | I14: 0.91 | J14: 1000
A15: gs-access-high-yield-etf | B15: GS Access High Yield ETF | C15: High Yield | D15: ETF | E15: Passive | F15: Internal | G15: USD | H15: Daily | I15: 0.34
A16: gs-access-em-usd-bond-etf | B16: GS Access EM USD Bond ETF | C16: EM Debt | D16: ETF | E16: Passive | F16: Internal | G16: USD | H16: Daily | I16: 0.39
A17: gs-access-us-large-cap-etf | B17: GS Access US Large Cap ETF | C17: US Large Cap | D17: ETF | E17: Passive | F17: Internal | G17: USD | H17: Daily | I17: 0.09
A18: gs-us-equity-insights-fund | B18: GS US Equity Insights Fund | C18: US All Cap | D18: Mutual Fund | E18: Active | F18: Internal | G18: USD | H18: Daily | I18: 0.71 | J18: 1000
A19: northbrook-intl-equity | B19: Northbrook Intl Equity | C19: Intl Developed | D19: Mutual Fund | E19: Active | F19: External | G19: Local | H19: Daily | I19: 0.68 | J19: 1000
A20: gs-emerging-markets-equity | B20: GS Emerging Markets Equity | C20: Emerging Markets | D20: Mutual Fund | E20: Active | F20: Internal | G20: Local | H20: Daily | I20: 1.12 | J20: 1000
A21: gs-access-intl-equity-etf | B21: GS Access Intl Equity ETF | C21: Intl Developed | D21: ETF | E21: Passive | F21: Internal | G21: Local | H21: Daily | I21: 0.25
A22: gs-access-em-equity-etf | B22: GS Access EM Equity ETF | C22: Emerging Markets | D22: ETF | E22: Passive | F22: Internal | G22: Local | H22: Daily | I22: 0.37
A23: gs-concentrated-growth-sma | B23: GS Concentrated Growth SMA | C23: US Large Cap | D23: SMA | E23: Active | F23: Internal | G23: USD | H23: Daily | I23: 0.55 | J23: 5000000
A24: gs-us-focused-value-sma | B24: GS US Focused Value SMA | C24: US Large Cap | D24: SMA | E24: Active | F24: Internal | G24: USD | H24: Daily | I24: 0.55 | J24: 5000000
A25: northbrook-focused-intl | B25: Northbrook Focused Intl | C25: Intl Developed | D25: Mutual Fund | E25: Active | F25: External | G25: Local | H25: Daily | I25: 0.94 | J25: 1000
A26: gs-hedgeworks-multi-strategy | B26: GS HedgeWorks Multi-Strategy | C26: Multi-Strategy | D26: SMA | E26: Active | F26: Internal | G26: USD | H26: Quarterly | I26: 1.35 | J26: 5000000
A27: calderwood-global-macro | B27: Calderwood Global Macro | C27: Global Macro | D27: SMA | E27: Active | F27: External | G27: USD | H27: Quarterly | I27: 1.48 | J27: 5000000
A28: ashfield-select-equity-l-s | B28: Ashfield Select Equity L/S | C28: Equity Long/Short | D28: SMA | E28: Active | F28: External | G28: USD | H28: Quarterly | I28: 1.62 | J28: 5000000
A29: northbrook-relative-value | B29: Northbrook Relative Value | C29: Relative Value | D29: SMA | E29: Active | F29: External | G29: USD | H29: Monthly | I29: 1.55 | J29: 5000000
A30: gs-absolute-return-tracker | B30: GS Absolute Return Tracker | C30: Multi-Strategy | D30: Mutual Fund | E30: Active | F30: Internal | G30: USD | H30: Daily | I30: 0.96 | J30: 1000
A31: gs-managed-futures-strategy | B31: GS Managed Futures Strategy | C31: Managed Futures | D31: Mutual Fund | E31: Active | F31: Internal | G31: USD | H31: Daily | I31: 1.08 | J31: 1000
A32: gs-vintage-fund-ix | B32: GS Vintage Fund IX | C32: Secondaries | D32: SMA | E32: Active | F32: Internal | G32: USD | H32: Drawdown | I32: 1.25 | J32: 5000000
A33: gs-private-markets-buyout | B33: GS Private Markets Buyout | C33: Buyout | D33: SMA | E33: Active | F33: Internal | G33: USD | H33: Drawdown | I33: 1.45 | J33: 5000000
A34: gs-growth-equity-partners | B34: GS Growth Equity Partners | C34: Growth | D34: SMA | E34: Active | F34: Internal | G34: USD | H34: Drawdown | I34: 1.5 | J34: 5000000
... A44: gs-esg-us-corporate-bond-fund | B44: GS ESG US Corporate Bond Fund | C44: IG Corporate | D44: Mutual Fund | E44: Active | F44: Internal | G44: USD | H44: Daily | I44: 0.44 | J44: 1000
A45: gs-access-esg-aggregate-etf | B45: GS Access ESG Aggregate ETF | C45: Aggregate | D45: ETF | E45: Passive | F45: Internal | G45: USD | H45: Daily | I45: 0.16
A46: gs-green-bond-fund | B46: GS Green Bond Fund | C46: Green Bonds | D46: Mutual Fund | E46: Active | F46: Internal | G46: USD | H46: Daily | I46: 0.48 | J46: 1000
A47: ashfield-social-impact-bond | B47: Ashfield Social Impact Bond | C47: Social Bonds | D47: Mutual Fund | E47: Active | F47: External | G47: Local | H47: Daily | I47: 0.62 | J47: 1000
A48: gs-esg-high-yield-fund | B48: GS ESG High Yield Fund | C48: High Yield | D48: Mutual Fund | E48: Active | F48: Internal | G48: USD | H48: Daily | I48: 0.76 | J48: 1000
A49: gs-esg-emerging-markets-debt | B49: GS ESG Emerging Markets Debt | C49: EM Debt | D49: Mutual Fund | E49: Active | F49: Internal | G49: USD | H49: Daily | I49: 0.89 | J49: 1000
...
